<?xml version="1.0" encoding="utf-8"?>
<!-- Flat URDF for Trossen wxai (follower variant) - generated from wxai.urdf.xacro -->
<!-- Used by cuRobo for motion planning. Mesh paths are relative to external_asset_path. -->
<robot name="wxai">

  <material name="trossen_black">
    <color rgba="0.2 0.2 0.2 1.0"/>
  </material>

  <!-- ====== Base Link ====== -->
  <link name="base_link">
    <inertial>
      <origin xyz="-0.00014175 -0.00005228 0.03175177" rpy="0 0 0"/>
      <mass value="0.45969858"/>
      <inertia ixx="0.00041660" ixy="0.00000011" ixz="-0.00000454"
               iyy="0.00044896" iyz="-0.00000078" izz="0.00021403"/>
    </inertial>
    <visual>
      <geometry><mesh filename="../../../trossen_arm_ros/trossen_arm_description/meshes/wxai/base_link.stl"/></geometry>
      <material name="trossen_black"/>
    </visual>
    <collision>
      <geometry><mesh filename="../../../trossen_arm_ros/trossen_arm_description/meshes/wxai/base_link.stl"/></geometry>
    </collision>
  </link>

  <!-- ====== Link 1 ====== -->
  <link name="link_1">
    <inertial>
      <origin xyz="-0.00011075 0.00171176 0.02044592" rpy="0 0 0"/>
      <mass value="0.15270428"/>
      <inertia ixx="0.00018509" ixy="-0.00000191" ixz="-0.00001436"
               iyy="0.00008358" iyz="-0.00000130" izz="0.00019219"/>
    </inertial>
    <visual>
      <geometry><mesh filename="../../../trossen_arm_ros/trossen_arm_description/meshes/wxai/link_1.stl"/></geometry>
      <material name="trossen_black"/>
    </visual>
    <collision>
      <geometry><mesh filename="../../../trossen_arm_ros/trossen_arm_description/meshes/wxai/link_1.stl"/></geometry>
    </collision>
  </link>

  <joint name="joint_0" type="revolute">
    <origin xyz="0 0 0.05725" rpy="0 0 0"/>
    <parent link="base_link"/>
    <child link="link_1"/>
    <axis xyz="0 0 1"/>
    <limit lower="-3.10433" upper="3.10433" effort="27.0" velocity="3.375"/>
  </joint>

  <!-- ====== Link 2 ====== -->
  <link name="link_2">
    <inertial>
      <origin xyz="-0.13121451 -0.00292583 0.00021345" rpy="0 0 0"/>
      <mass value="1.15316319"/>
      <inertia ixx="0.00102632" ixy="-0.00000319" ixz="-0.00002679"
               iyy="0.01736118" iyz="-0.00000193" izz="0.01794489"/>
    </inertial>
    <visual>
      <geometry><mesh filename="../../../trossen_arm_ros/trossen_arm_description/meshes/wxai/link_2.stl"/></geometry>
      <material name="trossen_black"/>
    </visual>
    <collision>
      <geometry><mesh filename="../../../trossen_arm_ros/trossen_arm_description/meshes/wxai/link_2.stl"/></geometry>
    </collision>
  </link>

  <joint name="joint_1" type="revolute">
    <origin xyz="0.02 0 0.04625" rpy="0 0 0"/>
    <parent link="link_1"/>
    <child link="link_2"/>
    <axis xyz="0 1 0"/>
    <limit lower="-0.05" upper="3.14159265" effort="27.0" velocity="3.375"/>
  </joint>

  <!-- ====== Link 3 ====== -->
  <link name="link_3">
    <inertial>
      <origin xyz="0.18083602 -0.00094090 0.05554937" rpy="0 0 0"/>
      <mass value="0.68666638"/>
      <inertia ixx="0.00064876" ixy="0.00009128" ixz="-0.00052002"
               iyy="0.00547407" iyz="0.00001159" izz="0.00561509"/>
    </inertial>
    <visual>
      <geometry><mesh filename="../../../trossen_arm_ros/trossen_arm_description/meshes/wxai/link_3.stl"/></geometry>
      <material name="trossen_black"/>
    </visual>
    <collision>
      <geometry><mesh filename="../../../trossen_arm_ros/trossen_arm_description/meshes/wxai/link_3.stl"/></geometry>
    </collision>
  </link>

  <joint name="joint_2" type="revolute">
    <origin xyz="-0.264 0 0" rpy="0 0 0"/>
    <parent link="link_2"/>
    <child link="link_3"/>
    <axis xyz="0 -1 0"/>
    <limit lower="-0.05" upper="2.35619449" effort="27.0" velocity="3.375"/>
  </joint>

  <!-- ====== Link 4 ====== -->
  <link name="link_4">
    <inertial>
      <origin xyz="0.05797842 0.00027145 0.05884447" rpy="0 0 0"/>
      <mass value="0.45789905"/>
      <inertia ixx="0.00053839" ixy="0.00000690" ixz="-0.00018164"
               iyy="0.00066138" iyz="0.00000724" izz="0.00042116"/>
    </inertial>
    <visual>
      <geometry><mesh filename="../../../trossen_arm_ros/trossen_arm_description/meshes/wxai/link_4.stl"/></geometry>
      <material name="trossen_black"/>
    </visual>
    <collision>
      <geometry><mesh filename="../../../trossen_arm_ros/trossen_arm_description/meshes/wxai/link_4.stl"/></geometry>
    </collision>
  </link>

  <joint name="joint_3" type="revolute">
    <origin xyz="0.245 0 0.06" rpy="0 0 0"/>
    <parent link="link_3"/>
    <child link="link_4"/>
    <axis xyz="0 -1 0"/>
    <limit lower="-1.62079633" upper="1.62079633" effort="7.0" velocity="7.0"/>
  </joint>

  <!-- ====== Link 5 ====== -->
  <link name="link_5">
    <inertial>
      <origin xyz="0.00412447 -0.00001138 -0.04283184" rpy="0 0 0"/>
      <mass value="0.36693910"/>
      <inertia ixx="0.00018912" ixy="-0.00000045" ixz="0.00000090"
               iyy="0.00032062" iyz="0.00000003" izz="0.00026750"/>
    </inertial>
    <visual>
      <geometry><mesh filename="../../../trossen_arm_ros/trossen_arm_description/meshes/wxai/link_5.stl"/></geometry>
      <material name="trossen_black"/>
    </visual>
    <collision>
      <geometry><mesh filename="../../../trossen_arm_ros/trossen_arm_description/meshes/wxai/link_5.stl"/></geometry>
    </collision>
  </link>

  <joint name="joint_4" type="revolute">
    <origin xyz="0.06775 0 0.0455" rpy="0 0 0"/>
    <parent link="link_4"/>
    <child link="link_5"/>
    <axis xyz="0 0 -1"/>
    <limit lower="-1.62079633" upper="1.62079633" effort="7.0" velocity="7.0"/>
  </joint>

  <!-- ====== Link 6 ====== -->
  <link name="link_6">
    <inertial>
      <origin xyz="0.04572768 -0.00000726 0.00001402" rpy="0 0 0"/>
      <mass value="0.55469347"/>
      <inertia ixx="0.00082429" ixy="-0.00000051" ixz="0.00000010"
               iyy="0.00048759" iyz="0.00000004" izz="0.00108600"/>
    </inertial>
    <visual>
      <geometry><mesh filename="../../../trossen_arm_ros/trossen_arm_description/meshes/wxai/link_6.stl"/></geometry>
      <material name="trossen_black"/>
    </visual>
    <collision>
      <geometry><mesh filename="../../../trossen_arm_ros/trossen_arm_description/meshes/wxai/link_6.stl"/></geometry>
    </collision>
  </link>

  <joint name="joint_5" type="revolute">
    <origin xyz="0.02895 0 -0.0455" rpy="0 0 0"/>
    <parent link="link_5"/>
    <child link="link_6"/>
    <axis xyz="1 0 0"/>
    <limit lower="-3.19159265" upper="3.19159265" effort="7.0" velocity="7.0"/>
  </joint>

  <!-- ====== Carriage Right (gripper) ====== -->
  <link name="carriage_right">
    <inertial>
      <origin xyz="-0.00889602 0.00403514 0.00457901" rpy="0 0 0"/>
      <mass value="0.05036313"/>
      <inertia ixx="0.00001736" ixy="-0.00000165" ixz="-0.00000104"
               iyy="0.00000591" iyz="-0.00000172" izz="0.00001378"/>
    </inertial>
    <visual>
      <geometry><mesh filename="../../../trossen_arm_ros/trossen_arm_description/meshes/wxai/carriage_right.stl"/></geometry>
      <material name="trossen_black"/>
    </visual>
    <collision>
      <geometry><mesh filename="../../../trossen_arm_ros/trossen_arm_description/meshes/wxai/carriage_right.stl"/></geometry>
    </collision>
  </link>

  <joint name="right_carriage_joint" type="prismatic">
    <origin xyz="0.0865 -0.023 0" rpy="0 0 0"/>
    <parent link="link_6"/>
    <child link="carriage_right"/>
    <axis xyz="0 -1 0"/>
    <limit lower="0.0" upper="0.044" effort="400.0" velocity="0.0875"/>
  </joint>

  <!-- ====== Carriage Left (gripper) ====== -->
  <link name="carriage_left">
    <inertial>
      <origin xyz="-0.00889602 -0.00403515 -0.00457908" rpy="0 0 0"/>
      <mass value="0.05036313"/>
      <inertia ixx="0.00001736" ixy="-0.00000165" ixz="-0.00000104"
               iyy="0.00000591" iyz="-0.00000172" izz="0.00001378"/>
    </inertial>
    <visual>
      <geometry><mesh filename="../../../trossen_arm_ros/trossen_arm_description/meshes/wxai/carriage_left.stl"/></geometry>
      <material name="trossen_black"/>
    </visual>
    <collision>
      <geometry><mesh filename="../../../trossen_arm_ros/trossen_arm_description/meshes/wxai/carriage_left.stl"/></geometry>
    </collision>
  </link>

  <joint name="left_carriage_joint" type="prismatic">
    <origin xyz="0.0865 0.023 0" rpy="0 0 0"/>
    <parent link="link_6"/>
    <child link="carriage_left"/>
    <axis xyz="0 1 0"/>
    <limit lower="0.0" upper="0.044" effort="400.0" velocity="0.0875"/>
  </joint>

  <!-- ====== Gripper Left (follower variant) ====== -->
  <link name="gripper_left">
    <inertial>
      <origin xyz="0.01893993 -0.00901223 -0.00215453" rpy="0 0 0"/>
      <mass value="0.03090787"/>
      <inertia ixx="0.00000769" ixy="0.00000321" ixz="0.00000029"
               iyy="0.00001487" iyz="-0.00000020" izz="0.00001184"/>
    </inertial>
    <visual>
      <geometry><mesh filename="../../../trossen_arm_ros/trossen_arm_description/meshes/wxai/gripper_left.stl"/></geometry>
      <material name="trossen_black"/>
    </visual>
    <collision>
      <geometry><mesh filename="../../../trossen_arm_ros/trossen_arm_description/meshes/wxai/gripper_left.stl"/></geometry>
    </collision>
  </link>

  <joint name="left_gripper_joint" type="fixed">
    <origin xyz="0 0 0" rpy="0 0 0"/>
    <parent link="carriage_left"/>
    <child link="gripper_left"/>
  </joint>

  <!-- ====== Gripper Right (follower variant) ====== -->
  <link name="gripper_right">
    <inertial>
      <origin xyz="0.01893989 0.00901216 -0.00215461" rpy="0 0 0"/>
      <mass value="0.03090786"/>
      <inertia ixx="0.00000769" ixy="-0.00000321" ixz="0.00000029"
               iyy="0.00001487" iyz="0.00000020" izz="0.00001184"/>
    </inertial>
    <visual>
      <geometry><mesh filename="../../../trossen_arm_ros/trossen_arm_description/meshes/wxai/gripper_right.stl"/></geometry>
      <material name="trossen_black"/>
    </visual>
    <collision>
      <geometry><mesh filename="../../../trossen_arm_ros/trossen_arm_description/meshes/wxai/gripper_right.stl"/></geometry>
    </collision>
  </link>

  <joint name="right_gripper_joint" type="fixed">
    <origin xyz="0 0 0" rpy="0 0 0"/>
    <parent link="carriage_right"/>
    <child link="gripper_right"/>
  </joint>

  <!-- ====== Spatula (attached to gripper_right) ====== -->
  <link name="spatula">
    <inertial>
      <origin xyz="0 0 0" rpy="0 0 0"/>
      <mass value="0.05"/>
      <inertia ixx="0.00001" ixy="0" ixz="0"
               iyy="0.00001" iyz="0" izz="0.00001"/>
    </inertial>
    <visual>
      <geometry><mesh filename="../../../trossen_arm_ros/trossen_arm_description/meshes/wxai/spatula.stl"/></geometry>
      <material name="trossen_black"/>
    </visual>
    <collision>
      <geometry><mesh filename="../../../trossen_arm_ros/trossen_arm_description/meshes/wxai/spatula.stl"/></geometry>
    </collision>
  </link>

  <joint name="spatula_joint" type="fixed">
    <origin xyz="0.01003 0.04218 0.0041" rpy="0 0 0"/>
    <parent link="gripper_right"/>
    <child link="spatula"/>
  </joint>

  <!-- ====== Spatula Tip (planning EE frame) ====== -->
  <link name="spatula_tip"/>

  <joint name="spatula_tip_joint" type="fixed">
    <origin xyz="0.22 -0.012 0" rpy="0 0 0"/>
    <parent link="spatula"/>
    <child link="spatula_tip"/>
  </joint>

  <!-- ====== Camera Mount (follower variant) ====== -->
  <link name="camera_mount_d405">
    <inertial>
      <origin xyz="0.03023383 0.00679835 0.05006687" rpy="0 0 0"/>
      <mass value="0.04518012"/>
      <inertia ixx="0.00003426" ixy="-0.00000027" ixz="-0.00000309"
               iyy="0.00001980" iyz="-0.00000319" izz="0.00002470"/>
    </inertial>
    <visual>
      <geometry><mesh filename="../../../trossen_arm_ros/trossen_arm_description/meshes/wxai/camera_mount_d405.stl"/></geometry>
      <material name="trossen_black"/>
    </visual>
    <collision>
      <geometry><mesh filename="../../../trossen_arm_ros/trossen_arm_description/meshes/wxai/camera_mount_d405.stl"/></geometry>
    </collision>
  </link>

  <joint name="camera_mount_joint" type="fixed">
    <origin xyz="0.012 0 0" rpy="0 0 0"/>
    <parent link="link_6"/>
    <child link="camera_mount_d405"/>
  </joint>

  <!-- ====== EE Gripper Link (fixed frame at gripper tip) ====== -->
  <link name="ee_gripper_link"/>

  <joint name="ee_gripper" type="fixed">
    <origin xyz="0.156062 0 0" rpy="0 0 0"/>
    <parent link="link_6"/>
    <child link="ee_gripper_link"/>
  </joint>

</robot>
